<?xml version="1.0"?>
<robot xmlns:xacro="http://www.ros.org/wiki/xacro">

    <xacro:include filename="inertial_macros.xacro" />


    <material name="white">
        <color rgba="1 1 1 1" />
    </material>

    <material name="orange">
        <color rgba="1 0.3 0.1 1" />
    </material>

    <material name="blue">
        <color rgba="0.2 0.2 1 1" />
    </material>

    <material name="black">
        <color rgba="0 0 0 1" />
    </material>

    <!-- base_link -->
    <link name="base_link">
    </link>

    <!-- chassis + base_link Joint -->

    <joint name="chassis_joint" type="fixed">
        <parent link="base_link" />
        <child link="chassis" />
        <origin xyz="-0.1 0 0" />
    </joint>

    <!-- chassis link -->

    <link name="chassis">
        <visual>
            <origin xyz="0.15 0 0.075" rpy="0 0 0" />
            <geometry>
                <mesh filename="package://jbot2/description/meshes/chassis.stl" scale="0.001 0.001 0.001" />
            </geometry>
            <material name="white" />
        </visual>
        <collision>
            <origin xyz="0.15 0 0.075" rpy="0 0 0" />
            <geometry>
                <mesh filename="package://jbot2/description/meshes/chassis.stl" scale="0.001 0.001 0.001"/>
                <!-- <box size="0.3 0.3 0.15" /> -->
            </geometry>
        </collision>
        <xacro:inertial_box mass="0.5" x="0.3" y="0.3" z="0.15">
            <origin xyz="0.15 0 0.075" rpy="0 0 0" />
        </xacro:inertial_box>
    </link>

    <gazebo reference="chassis"> 
        <material>Gazebo/White</material>
        <geometry>
            <mesh package="$(find jbot2)/description/meshes/chassis.stl" scale="0.001 0.001 0.001"/>
        </geometry>
    </gazebo>

    <!-- fchassis link -->
    <!-- chassis + base_link Joint -->

    <joint name="chassis_joint" type="fixed">
        <parent link="base_link" />
        <child link="fchassis" />
        <origin xyz="-0.1 0 0" />
    </joint>

    <!-- fhassis link -->

    <link name="fchassis">
        <visual>
            <origin xyz="0.15 0 0.075" rpy="0 0 0" />
            <geometry>
                <mesh filename="package://jbot2/description/meshes2/chassis.stl" scale="0.001 0.001 0.001" />
            </geometry>
            <material name="white" />
        </visual>
        <collision>
            <origin xyz="0.15 0 0.075" rpy="0 0 0" />
            <geometry>
                <mesh filename="package://jbot2/description/meshes2/chassis.stl" scale="0.001 0.001 0.001"/>
                <!-- <box size="0.3 0.3 0.15" /> -->
            </geometry>
        </collision>
        <xacro:inertial_box mass="0.5" x="0.3" y="0.3" z="0.15">
            <origin xyz="0.15 0 0.075" rpy="0 0 0" />
        </xacro:inertial_box>
    </link>

    <gazebo reference="fchassis"> 
        <material>Gazebo/White</material>
        <geometry>
            <mesh package="$(find jbot2)/description/meshes2/chassis.stl" scale="0.001 0.001 0.001"/>
        </geometry>
    </gazebo>

    
    <!-- LEFT WHEEL -->

    <!-- left_wheel + base_link Joint -->

    <joint name="left_wheel_joint" type="continuous">
        <parent link="base_link" />
        <child link="left_wheel" />
        <origin xyz="0 0.175 0" rpy="-${pi/2} 0 0" />
        <axis xyz="0 0 1" />
    </joint>

    <!-- left_wheel link -->

    <link name="left_wheel">
        <visual>
            <geometry>
                <mesh filename="package://jbot2/description/meshes2/fl_wheel.stl" scale="0.001 0.001 0.001" />
            </geometry>
            <material name="blue" />
        </visual>
        <collision>
            <geometry>
                <mesh filename="package://jbot2/description/meshes2/fl_wheel.stl" scale="0.001 0.001 0.001" />
            </geometry>
        </collision>
        <xacro:inertial_cylinder mass="0.1" length="0.04" radius="0.05">
            <origin xyz="0 0 0" rpy="0 0 0" />
        </xacro:inertial_cylinder>
    </link>

    <gazebo reference="left_wheel"> 
        <material>Gazebo/Blue</material>
            <material>Gazebo/White</material>
        <geometry>
             <mesh package="$(find jbot2)/description/meshes2/fl_wheel.stl" scale="0.001 0.001 0.001"/>
        </geometry>
    </gazebo>
    
    <!-- RIGHT WHEEL -->
    <!-- right_wheel + base_link Joint -->

    <joint name="right_wheel_joint" type="continuous">
        <parent link="base_link" />
        <child link="right_wheel" />
        <origin xyz="0 -0.175 0" rpy="${pi/2} 0 0" />
        <axis xyz="0 0 -1" />
    </joint>

    <!-- right_wheel link -->

    <link name="right_wheel">
        <visual>
            <geometry>
                <mesh filename="package://jbot2/description/meshes2/fr_wheel.stl" scale="0.001 0.001 0.001" />
            </geometry>
            <material name="blue" />
        </visual>
        <collision>
            <geometry>
                <mesh filename="package://jbot2/description/meshes2/fr_wheel.stl" scale="0.001 0.001 0.001" />
            </geometry>
        </collision>
        <xacro:inertial_cylinder mass="0.1" length="0.04" radius="0.05">
            <origin xyz="0 0 0" rpy="0 0 0" />
        </xacro:inertial_cylinder>
    </link>

    <gazebo reference="right_wheel"> 
        <material>Gazebo/Blue</material>
        <geometry>
             <mesh package="$(find jbot2)/description/meshes2/fr_wheel.stl" scale="0.001 0.001 0.001"/>
        </geometry>
    </gazebo>

    <!-- CASTER WHEEL -->
    <!-- caster_wheel + chassis Joint -->

    <joint name="caster_wheel_joint" type="fixed">
        <parent link="chassis" />
        <child link="caster_wheel" />
        <origin xyz="0.24 0 0" rpy="0 0 0" />
    </joint>

    <!-- caster_wheel link -->

    <link name="caster_wheel">
        <visual>
            <geometry>
                <sphere radius="0.05" />
            </geometry>
            <material name="black" />
        </visual>
        <collision>
            <geometry>
                <sphere radius="0.05" />
            </geometry>
        </collision>
        <xacro:inertial_sphere mass="0.1" radius="0.05">
            <origin xyz="0 0 0" rpy="0 0 0" />
        </xacro:inertial_sphere>
    </link>

    <gazebo reference="chasis"> 
        <material>Gazebo/Black</material>
        <mu1 value="0.001"/>
        <mu2 value="0.001"/>
    </gazebo>


</robot>